2025-06-30T02:29:59 {"block_run_id": 83, "block_uuid": "brewery_bronze_export", "pipeline_run_id": 12, "pipeline_schedule_id": 11, "pipeline_uuid": "elt_proj_breweries", "hostname": "4400563e4e3b", "block_type": "data_exporter", "level": "INFO", "message": "Start executing block with BlockExecutor.", "timestamp": 1751250599.062754, "uuid": "560e551a36b448a09f074ea96899a1e7"}
2025-06-30T02:30:00 {"block_run_id": 83, "block_uuid": "brewery_bronze_export", "pipeline_run_id": 12, "pipeline_schedule_id": 11, "pipeline_uuid": "elt_proj_breweries", "hostname": "4400563e4e3b", "block_type": "data_exporter", "level": "INFO", "message": "[Erro] Tentativa 1/3 falhou ao exportar para S3.", "timestamp": 1751250600.003557, "uuid": "386f06c8bc9c40908928807e15ff7037"}
2025-06-30T02:30:00 {"block_run_id": 83, "block_uuid": "brewery_bronze_export", "pipeline_run_id": 12, "pipeline_schedule_id": 11, "pipeline_uuid": "elt_proj_breweries", "hostname": "4400563e4e3b", "block_type": "data_exporter", "level": "INFO", "message": "Traceback (most recent call last):", "timestamp": 1751250600.006741, "uuid": "54e18ef3270d4821b18f795a596888ea"}
2025-06-30T02:30:00 {"block_run_id": 83, "block_uuid": "brewery_bronze_export", "pipeline_run_id": 12, "pipeline_schedule_id": 11, "pipeline_uuid": "elt_proj_breweries", "hostname": "4400563e4e3b", "block_type": "data_exporter", "level": "INFO", "message": "  File \"<string>\", line 38, in export_data_to_s3", "timestamp": 1751250600.008493, "uuid": "594d1479ad22441b91b7eb5b32a28bfc"}
2025-06-30T02:30:00 {"block_run_id": 83, "block_uuid": "brewery_bronze_export", "pipeline_run_id": 12, "pipeline_schedule_id": 11, "pipeline_uuid": "elt_proj_breweries", "hostname": "4400563e4e3b", "block_type": "data_exporter", "level": "INFO", "message": "  File \"/usr/local/lib/python3.10/site-packages/mage_ai/io/s3.py\", line 120, in export", "timestamp": 1751250600.010113, "uuid": "20aefcedd6e04e8485cc9f2fe42986fc"}
2025-06-30T02:30:00 {"block_run_id": 83, "block_uuid": "brewery_bronze_export", "pipeline_run_id": 12, "pipeline_schedule_id": 11, "pipeline_uuid": "elt_proj_breweries", "hostname": "4400563e4e3b", "block_type": "data_exporter", "level": "INFO", "message": "    self.client.put_object(Body=buffer, Bucket=bucket_name, Key=object_key)", "timestamp": 1751250600.012043, "uuid": "f893fcc18cde4202ace3fa6ab2639c72"}
2025-06-30T02:30:00 {"block_run_id": 83, "block_uuid": "brewery_bronze_export", "pipeline_run_id": 12, "pipeline_schedule_id": 11, "pipeline_uuid": "elt_proj_breweries", "hostname": "4400563e4e3b", "block_type": "data_exporter", "level": "INFO", "message": "  File \"/usr/local/lib/python3.10/site-packages/botocore/client.py\", line 530, in _api_call", "timestamp": 1751250600.014059, "uuid": "e8132546796541efa1c058a0045d4b91"}
2025-06-30T02:30:00 {"block_run_id": 83, "block_uuid": "brewery_bronze_export", "pipeline_run_id": 12, "pipeline_schedule_id": 11, "pipeline_uuid": "elt_proj_breweries", "hostname": "4400563e4e3b", "block_type": "data_exporter", "level": "INFO", "message": "    return self._make_api_call(operation_name, kwargs)", "timestamp": 1751250600.016057, "uuid": "bf27e027584b44ffb94810bcae544cf1"}
2025-06-30T02:30:00 {"block_run_id": 83, "block_uuid": "brewery_bronze_export", "pipeline_run_id": 12, "pipeline_schedule_id": 11, "pipeline_uuid": "elt_proj_breweries", "hostname": "4400563e4e3b", "block_type": "data_exporter", "level": "INFO", "message": "  File \"/usr/local/lib/python3.10/site-packages/botocore/client.py\", line 964, in _make_api_call", "timestamp": 1751250600.01802, "uuid": "b9854c402545477d96e70857dc3b525e"}
2025-06-30T02:30:00 {"block_run_id": 83, "block_uuid": "brewery_bronze_export", "pipeline_run_id": 12, "pipeline_schedule_id": 11, "pipeline_uuid": "elt_proj_breweries", "hostname": "4400563e4e3b", "block_type": "data_exporter", "level": "INFO", "message": "    raise error_class(parsed_response, operation_name)", "timestamp": 1751250600.019987, "uuid": "f1cc225a1b4f4aa9be8a014fa685c246"}
2025-06-30T02:30:00 {"block_run_id": 83, "block_uuid": "brewery_bronze_export", "pipeline_run_id": 12, "pipeline_schedule_id": 11, "pipeline_uuid": "elt_proj_breweries", "hostname": "4400563e4e3b", "block_type": "data_exporter", "level": "INFO", "message": "botocore.errorfactory.NoSuchBucket: An error occurred (NoSuchBucket) when calling the PutObject operation: The specified bucket does not exist", "timestamp": 1751250600.022175, "uuid": "93dc7ec769ad494d9d5aa0b8b4b130a2"}
2025-06-30T02:30:02 {"block_run_id": 83, "block_uuid": "brewery_bronze_export", "pipeline_run_id": 12, "pipeline_schedule_id": 11, "pipeline_uuid": "elt_proj_breweries", "hostname": "4400563e4e3b", "block_type": "data_exporter", "level": "INFO", "message": "[Erro] Tentativa 2/3 falhou ao exportar para S3.", "timestamp": 1751250602.908057, "uuid": "840702955b5240668aa3e9f5ea002509"}
2025-06-30T02:30:02 {"block_run_id": 83, "block_uuid": "brewery_bronze_export", "pipeline_run_id": 12, "pipeline_schedule_id": 11, "pipeline_uuid": "elt_proj_breweries", "hostname": "4400563e4e3b", "block_type": "data_exporter", "level": "INFO", "message": "Traceback (most recent call last):", "timestamp": 1751250602.910021, "uuid": "14f1edb549784c42a28638392218c43b"}
2025-06-30T02:30:02 {"block_run_id": 83, "block_uuid": "brewery_bronze_export", "pipeline_run_id": 12, "pipeline_schedule_id": 11, "pipeline_uuid": "elt_proj_breweries", "hostname": "4400563e4e3b", "block_type": "data_exporter", "level": "INFO", "message": "  File \"<string>\", line 38, in export_data_to_s3", "timestamp": 1751250602.91238, "uuid": "15ec3918f32b4dc396e33fcfa35494c2"}
2025-06-30T02:30:02 {"block_run_id": 83, "block_uuid": "brewery_bronze_export", "pipeline_run_id": 12, "pipeline_schedule_id": 11, "pipeline_uuid": "elt_proj_breweries", "hostname": "4400563e4e3b", "block_type": "data_exporter", "level": "INFO", "message": "  File \"/usr/local/lib/python3.10/site-packages/mage_ai/io/s3.py\", line 120, in export", "timestamp": 1751250602.914368, "uuid": "20712396de3842b691c70b283e7a5b5a"}
2025-06-30T02:30:02 {"block_run_id": 83, "block_uuid": "brewery_bronze_export", "pipeline_run_id": 12, "pipeline_schedule_id": 11, "pipeline_uuid": "elt_proj_breweries", "hostname": "4400563e4e3b", "block_type": "data_exporter", "level": "INFO", "message": "    self.client.put_object(Body=buffer, Bucket=bucket_name, Key=object_key)", "timestamp": 1751250602.916902, "uuid": "2a1b5fc0f14a4028acd4ce0496c5ccfe"}
2025-06-30T02:30:02 {"block_run_id": 83, "block_uuid": "brewery_bronze_export", "pipeline_run_id": 12, "pipeline_schedule_id": 11, "pipeline_uuid": "elt_proj_breweries", "hostname": "4400563e4e3b", "block_type": "data_exporter", "level": "INFO", "message": "  File \"/usr/local/lib/python3.10/site-packages/botocore/client.py\", line 530, in _api_call", "timestamp": 1751250602.919165, "uuid": "7d90b63724894d12a2cb31e0cd0cc654"}
2025-06-30T02:30:02 {"block_run_id": 83, "block_uuid": "brewery_bronze_export", "pipeline_run_id": 12, "pipeline_schedule_id": 11, "pipeline_uuid": "elt_proj_breweries", "hostname": "4400563e4e3b", "block_type": "data_exporter", "level": "INFO", "message": "    return self._make_api_call(operation_name, kwargs)", "timestamp": 1751250602.920795, "uuid": "08ebb30a04d34f5286fa6786108bca60"}
2025-06-30T02:30:02 {"block_run_id": 83, "block_uuid": "brewery_bronze_export", "pipeline_run_id": 12, "pipeline_schedule_id": 11, "pipeline_uuid": "elt_proj_breweries", "hostname": "4400563e4e3b", "block_type": "data_exporter", "level": "INFO", "message": "  File \"/usr/local/lib/python3.10/site-packages/botocore/client.py\", line 964, in _make_api_call", "timestamp": 1751250602.922404, "uuid": "89e805f65edb420e83864bf47c3a0429"}
2025-06-30T02:30:02 {"block_run_id": 83, "block_uuid": "brewery_bronze_export", "pipeline_run_id": 12, "pipeline_schedule_id": 11, "pipeline_uuid": "elt_proj_breweries", "hostname": "4400563e4e3b", "block_type": "data_exporter", "level": "INFO", "message": "    raise error_class(parsed_response, operation_name)", "timestamp": 1751250602.924289, "uuid": "a7af5d4293d343c5b9ddeadcc5bf3a4e"}
2025-06-30T02:30:02 {"block_run_id": 83, "block_uuid": "brewery_bronze_export", "pipeline_run_id": 12, "pipeline_schedule_id": 11, "pipeline_uuid": "elt_proj_breweries", "hostname": "4400563e4e3b", "block_type": "data_exporter", "level": "INFO", "message": "botocore.errorfactory.NoSuchBucket: An error occurred (NoSuchBucket) when calling the PutObject operation: The specified bucket does not exist", "timestamp": 1751250602.92603, "uuid": "7da22117e6824c4b9d70d256731cd997"}
2025-06-30T02:30:05 {"block_run_id": 83, "block_uuid": "brewery_bronze_export", "pipeline_run_id": 12, "pipeline_schedule_id": 11, "pipeline_uuid": "elt_proj_breweries", "hostname": "4400563e4e3b", "block_type": "data_exporter", "level": "INFO", "message": "[Erro] Tentativa 3/3 falhou ao exportar para S3.", "timestamp": 1751250605.691913, "uuid": "c1ac00ae2d5f49939473454122327456"}
2025-06-30T02:30:05 {"block_run_id": 83, "block_uuid": "brewery_bronze_export", "pipeline_run_id": 12, "pipeline_schedule_id": 11, "pipeline_uuid": "elt_proj_breweries", "hostname": "4400563e4e3b", "block_type": "data_exporter", "level": "INFO", "message": "Traceback (most recent call last):", "timestamp": 1751250605.693973, "uuid": "aa05f7a114cb44978dab1ac500dc2e9a"}
2025-06-30T02:30:05 {"block_run_id": 83, "block_uuid": "brewery_bronze_export", "pipeline_run_id": 12, "pipeline_schedule_id": 11, "pipeline_uuid": "elt_proj_breweries", "hostname": "4400563e4e3b", "block_type": "data_exporter", "level": "INFO", "message": "  File \"<string>\", line 38, in export_data_to_s3", "timestamp": 1751250605.695583, "uuid": "c925f6f216d04034993eee2f6304a921"}
2025-06-30T02:30:05 {"block_run_id": 83, "block_uuid": "brewery_bronze_export", "pipeline_run_id": 12, "pipeline_schedule_id": 11, "pipeline_uuid": "elt_proj_breweries", "hostname": "4400563e4e3b", "block_type": "data_exporter", "level": "INFO", "message": "  File \"/usr/local/lib/python3.10/site-packages/mage_ai/io/s3.py\", line 120, in export", "timestamp": 1751250605.700545, "uuid": "a1aa1f7cc75b49b286e68eee1c183ba2"}
2025-06-30T02:30:05 {"block_run_id": 83, "block_uuid": "brewery_bronze_export", "pipeline_run_id": 12, "pipeline_schedule_id": 11, "pipeline_uuid": "elt_proj_breweries", "hostname": "4400563e4e3b", "block_type": "data_exporter", "level": "INFO", "message": "    self.client.put_object(Body=buffer, Bucket=bucket_name, Key=object_key)", "timestamp": 1751250605.702739, "uuid": "342aee580ef848818ef09694475721eb"}
2025-06-30T02:30:05 {"block_run_id": 83, "block_uuid": "brewery_bronze_export", "pipeline_run_id": 12, "pipeline_schedule_id": 11, "pipeline_uuid": "elt_proj_breweries", "hostname": "4400563e4e3b", "block_type": "data_exporter", "level": "INFO", "message": "  File \"/usr/local/lib/python3.10/site-packages/botocore/client.py\", line 530, in _api_call", "timestamp": 1751250605.704715, "uuid": "f59989af331f4f399413f0ce2ac397b9"}
2025-06-30T02:30:05 {"block_run_id": 83, "block_uuid": "brewery_bronze_export", "pipeline_run_id": 12, "pipeline_schedule_id": 11, "pipeline_uuid": "elt_proj_breweries", "hostname": "4400563e4e3b", "block_type": "data_exporter", "level": "INFO", "message": "    return self._make_api_call(operation_name, kwargs)", "timestamp": 1751250605.706272, "uuid": "8c534cd703674e7c90c71f190952aa94"}
2025-06-30T02:30:05 {"block_run_id": 83, "block_uuid": "brewery_bronze_export", "pipeline_run_id": 12, "pipeline_schedule_id": 11, "pipeline_uuid": "elt_proj_breweries", "hostname": "4400563e4e3b", "block_type": "data_exporter", "level": "INFO", "message": "  File \"/usr/local/lib/python3.10/site-packages/botocore/client.py\", line 964, in _make_api_call", "timestamp": 1751250605.707883, "uuid": "8da6df6a06de45bea012063304304c34"}
2025-06-30T02:30:05 {"block_run_id": 83, "block_uuid": "brewery_bronze_export", "pipeline_run_id": 12, "pipeline_schedule_id": 11, "pipeline_uuid": "elt_proj_breweries", "hostname": "4400563e4e3b", "block_type": "data_exporter", "level": "INFO", "message": "    raise error_class(parsed_response, operation_name)", "timestamp": 1751250605.710192, "uuid": "5ed4505bfe2f4d93b55dbc41082eb22b"}
2025-06-30T02:30:05 {"block_run_id": 83, "block_uuid": "brewery_bronze_export", "pipeline_run_id": 12, "pipeline_schedule_id": 11, "pipeline_uuid": "elt_proj_breweries", "hostname": "4400563e4e3b", "block_type": "data_exporter", "level": "INFO", "message": "botocore.errorfactory.NoSuchBucket: An error occurred (NoSuchBucket) when calling the PutObject operation: The specified bucket does not exist", "timestamp": 1751250605.711746, "uuid": "7f043d822fef47079025f733db16175a"}
2025-06-30T02:30:04 {"block_run_id": 83, "block_uuid": "brewery_bronze_export", "pipeline_run_id": 12, "pipeline_schedule_id": 11, "pipeline_uuid": "elt_proj_breweries", "hostname": "4400563e4e3b", "block_type": "data_exporter", "level": "WARNING", "message": "Exception thrown when attempting to run <function BlockExecutor.execute.<locals>.__execute_with_retry at 0x714c468ea680>, attempt 1 of 1", "timestamp": 1751250604.997273, "uuid": "9006a2761fd846d08bbbbcdacafe4e3b", "error": "Traceback (most recent call last):\n  File \"<string>\", line 38, in export_data_to_s3\n  File \"/usr/local/lib/python3.10/site-packages/mage_ai/io/s3.py\", line 120, in export\n    self.client.put_object(Body=buffer, Bucket=bucket_name, Key=object_key)\n  File \"/usr/local/lib/python3.10/site-packages/botocore/client.py\", line 530, in _api_call\n    return self._make_api_call(operation_name, kwargs)\n  File \"/usr/local/lib/python3.10/site-packages/botocore/client.py\", line 964, in _make_api_call\n    raise error_class(parsed_response, operation_name)\nbotocore.errorfactory.NoSuchBucket: An error occurred (NoSuchBucket) when calling the PutObject operation: The specified bucket does not exist\n\nThe above exception was the direct cause of the following exception:\n\nTraceback (most recent call last):\n  File \"/usr/local/lib/python3.10/site-packages/mage_ai/shared/retry.py\", line 38, in retry_func\n    return func(*args, **kwargs)\n  File \"/usr/local/lib/python3.10/site-packages/mage_ai/data_preparation/executors/block_executor.py\", line 621, in __execute_with_retry\n    return self._execute(\n  File \"/usr/local/lib/python3.10/site-packages/mage_ai/data_preparation/executors/block_executor.py\", line 1154, in _execute\n    result = self.block.execute_sync(\n  File \"/usr/local/lib/python3.10/site-packages/mage_ai/data_preparation/models/block/__init__.py\", line 1691, in execute_sync\n    return __execute()\n  File \"/usr/local/lib/python3.10/site-packages/mage_ai/data_preparation/models/block/__init__.py\", line 1668, in __execute\n    raise err\n  File \"/usr/local/lib/python3.10/site-packages/mage_ai/data_preparation/models/block/__init__.py\", line 1570, in __execute\n    output = self.execute_block(\n  File \"/usr/local/lib/python3.10/site-packages/mage_ai/data_preparation/models/block/__init__.py\", line 1910, in execute_block\n    outputs = self._execute_block(\n  File \"/usr/local/lib/python3.10/site-packages/mage_ai/data_preparation/models/block/__init__.py\", line 2073, in _execute_block\n    outputs = self.execute_block_function(\n  File \"/usr/local/lib/python3.10/site-packages/mage_ai/data_preparation/models/block/__init__.py\", line 2169, in execute_block_function\n    output = block_function_updated(*input_vars, **global_vars)\n  File \"<string>\", line 55, in export_data_to_s3\nRuntimeError: [Falha Cr\u00edtica] N\u00e3o foi poss\u00edvel exportar os dados para s3://db-inbev-bronze-layer1/breweries_raw.json ap\u00f3s 3 tentativas.\n", "error_stack": ["  File \"/usr/local/bin/mage\", line 8, in <module>\n    sys.exit(app())\n", "  File \"/usr/local/lib/python3.10/site-packages/typer/main.py\", line 311, in __call__\n    return get_command(self)(*args, **kwargs)\n", "  File \"/usr/local/lib/python3.10/site-packages/click/core.py\", line 1442, in __call__\n    return self.main(*args, **kwargs)\n", "  File \"/usr/local/lib/python3.10/site-packages/typer/core.py\", line 778, in main\n    return _main(\n", "  File \"/usr/local/lib/python3.10/site-packages/typer/core.py\", line 216, in _main\n    rv = self.invoke(ctx)\n", "  File \"/usr/local/lib/python3.10/site-packages/click/core.py\", line 1830, in invoke\n    return _process_result(sub_ctx.command.invoke(sub_ctx))\n", "  File \"/usr/local/lib/python3.10/site-packages/click/core.py\", line 1226, in invoke\n    return ctx.invoke(self.callback, **ctx.params)\n", "  File \"/usr/local/lib/python3.10/site-packages/click/core.py\", line 794, in invoke\n    return callback(*args, **kwargs)\n", "  File \"/usr/local/lib/python3.10/site-packages/typer/main.py\", line 683, in wrapper\n    return callback(**use_params)  # type: ignore\n", "  File \"/usr/local/lib/python3.10/site-packages/mage_ai/cli/main.py\", line 147, in start\n    start_server(\n", "  File \"/usr/local/lib/python3.10/site-packages/mage_ai/server/server.py\", line 809, in start_server\n    scheduler_manager.start_scheduler()\n", "  File \"/usr/local/lib/python3.10/site-packages/mage_ai/server/scheduler_manager.py\", line 108, in start_scheduler\n    proc.start()\n", "  File \"/usr/local/lib/python3.10/multiprocessing/process.py\", line 121, in start\n    self._popen = self._Popen(self)\n", "  File \"/usr/local/lib/python3.10/multiprocessing/context.py\", line 224, in _Popen\n    return _default_context.get_context().Process._Popen(process_obj)\n", "  File \"/usr/local/lib/python3.10/multiprocessing/context.py\", line 281, in _Popen\n    return Popen(process_obj)\n", "  File \"/usr/local/lib/python3.10/multiprocessing/popen_fork.py\", line 19, in __init__\n    self._launch(process_obj)\n", "  File \"/usr/local/lib/python3.10/multiprocessing/popen_fork.py\", line 71, in _launch\n    code = process_obj._bootstrap(parent_sentinel=child_r)\n", "  File \"/usr/local/lib/python3.10/multiprocessing/process.py\", line 314, in _bootstrap\n    self.run()\n", "  File \"/usr/local/lib/python3.10/multiprocessing/process.py\", line 108, in run\n    self._target(*self._args, **self._kwargs)\n", "  File \"/usr/local/lib/python3.10/site-packages/mage_ai/orchestration/db/process.py\", line 15, in start_session_and_run\n    results = target(*args)\n", "  File \"/usr/local/lib/python3.10/site-packages/mage_ai/server/scheduler_manager.py\", line 60, in run_scheduler\n    LoopTimeTrigger().start()\n", "  File \"/usr/local/lib/python3.10/site-packages/mage_ai/orchestration/triggers/loop_time_trigger.py\", line 14, in start\n    self.run()\n", "  File \"/usr/local/lib/python3.10/site-packages/mage_ai/orchestration/triggers/time_trigger.py\", line 11, in run\n    schedule_all()\n", "  File \"/usr/local/lib/python3.10/site-packages/mage_ai/orchestration/pipeline_scheduler_original.py\", line 1730, in schedule_all\n    PipelineScheduler(r).schedule()\n", "  File \"/usr/local/lib/python3.10/site-packages/mage_ai/orchestration/db/__init__.py\", line 159, in func_with_rollback\n    return func(*args, **kwargs)\n", "  File \"/usr/local/lib/python3.10/site-packages/mage_ai/orchestration/pipeline_scheduler_original.py\", line 333, in schedule\n    self.__schedule_blocks(block_runs)\n", "  File \"/usr/local/lib/python3.10/site-packages/mage_ai/orchestration/pipeline_scheduler_original.py\", line 640, in __schedule_blocks\n    job_manager.add_job(\n", "  File \"/usr/local/lib/python3.10/site-packages/mage_ai/orchestration/job_manager.py\", line 20, in add_job\n    self.queue.enqueue(job_id, target, *args, **kwargs)\n", "  File \"/usr/local/lib/python3.10/site-packages/mage_ai/orchestration/queue/process_queue.py\", line 122, in enqueue\n    self.start_worker_pool()\n", "  File \"/usr/local/lib/python3.10/site-packages/mage_ai/orchestration/queue/process_queue.py\", line 199, in start_worker_pool\n    self.worker_pool_proc.start()\n", "  File \"/usr/local/lib/python3.10/multiprocessing/process.py\", line 121, in start\n    self._popen = self._Popen(self)\n", "  File \"/usr/local/lib/python3.10/multiprocessing/context.py\", line 224, in _Popen\n    return _default_context.get_context().Process._Popen(process_obj)\n", "  File \"/usr/local/lib/python3.10/multiprocessing/context.py\", line 281, in _Popen\n    return Popen(process_obj)\n", "  File \"/usr/local/lib/python3.10/multiprocessing/popen_fork.py\", line 19, in __init__\n    self._launch(process_obj)\n", "  File \"/usr/local/lib/python3.10/multiprocessing/popen_fork.py\", line 71, in _launch\n    code = process_obj._bootstrap(parent_sentinel=child_r)\n", "  File \"/usr/local/lib/python3.10/multiprocessing/process.py\", line 314, in _bootstrap\n    self.run()\n", "  File \"/usr/local/lib/python3.10/multiprocessing/process.py\", line 108, in run\n    self._target(*self._args, **self._kwargs)\n", "  File \"/usr/local/lib/python3.10/site-packages/mage_ai/orchestration/queue/process_queue.py\", line 353, in poll_job_and_execute\n    worker.start()\n", "  File \"/usr/local/lib/python3.10/multiprocessing/process.py\", line 121, in start\n    self._popen = self._Popen(self)\n", "  File \"/usr/local/lib/python3.10/multiprocessing/context.py\", line 224, in _Popen\n    return _default_context.get_context().Process._Popen(process_obj)\n", "  File \"/usr/local/lib/python3.10/multiprocessing/context.py\", line 281, in _Popen\n    return Popen(process_obj)\n", "  File \"/usr/local/lib/python3.10/multiprocessing/popen_fork.py\", line 19, in __init__\n    self._launch(process_obj)\n", "  File \"/usr/local/lib/python3.10/multiprocessing/popen_fork.py\", line 71, in _launch\n    code = process_obj._bootstrap(parent_sentinel=child_r)\n", "  File \"/usr/local/lib/python3.10/multiprocessing/process.py\", line 314, in _bootstrap\n    self.run()\n", "  File \"/usr/local/lib/python3.10/site-packages/newrelic/api/background_task.py\", line 117, in wrapper\n    return wrapped(*args, **kwargs)\n", "  File \"/usr/local/lib/python3.10/site-packages/mage_ai/orchestration/queue/process_queue.py\", line 317, in run\n    start_session_and_run(args[1], *args[2], **args[3])\n", "  File \"/usr/local/lib/python3.10/site-packages/mage_ai/orchestration/db/process.py\", line 15, in start_session_and_run\n    results = target(*args)\n", "  File \"/usr/local/lib/python3.10/site-packages/mage_ai/orchestration/pipeline_scheduler_original.py\", line 1235, in run_block\n    return ExecutorFactory.get_block_executor(\n", "  File \"/usr/local/lib/python3.10/site-packages/mage_ai/data_preparation/executors/block_executor.py\", line 647, in execute\n    result = __execute_with_retry()\n", "  File \"/usr/local/lib/python3.10/site-packages/mage_ai/shared/retry.py\", line 46, in retry_func\n    logger.warning(\n", "  File \"/usr/local/lib/python3.10/site-packages/mage_ai/data_preparation/logging/logger.py\", line 39, in warning\n    self.__send_message('warning', message, **kwargs)\n", "  File \"/usr/local/lib/python3.10/site-packages/mage_ai/data_preparation/logging/logger.py\", line 65, in __send_message\n    data['error_stack'] = traceback.format_stack()\n"], "error_stacktrace": "[Falha Cr\u00edtica] N\u00e3o foi poss\u00edvel exportar os dados para s3://db-inbev-bronze-layer1/breweries_raw.json ap\u00f3s 3 tentativas."}
2025-06-30T02:30:05 {"block_run_id": 83, "block_uuid": "brewery_bronze_export", "pipeline_run_id": 12, "pipeline_schedule_id": 11, "pipeline_uuid": "elt_proj_breweries", "hostname": "4400563e4e3b", "block_type": "data_exporter", "level": "EXCEPTION", "message": "Failed to execute block brewery_bronze_export", "timestamp": 1751250605.001585, "uuid": "b47983db0d3143f5a0e20decb49f5983", "error": "Traceback (most recent call last):\n  File \"<string>\", line 38, in export_data_to_s3\n  File \"/usr/local/lib/python3.10/site-packages/mage_ai/io/s3.py\", line 120, in export\n    self.client.put_object(Body=buffer, Bucket=bucket_name, Key=object_key)\n  File \"/usr/local/lib/python3.10/site-packages/botocore/client.py\", line 530, in _api_call\n    return self._make_api_call(operation_name, kwargs)\n  File \"/usr/local/lib/python3.10/site-packages/botocore/client.py\", line 964, in _make_api_call\n    raise error_class(parsed_response, operation_name)\nbotocore.errorfactory.NoSuchBucket: An error occurred (NoSuchBucket) when calling the PutObject operation: The specified bucket does not exist\n\nThe above exception was the direct cause of the following exception:\n\nTraceback (most recent call last):\n  File \"/usr/local/lib/python3.10/site-packages/mage_ai/data_preparation/executors/block_executor.py\", line 647, in execute\n    result = __execute_with_retry()\n  File \"/usr/local/lib/python3.10/site-packages/mage_ai/shared/retry.py\", line 54, in retry_func\n    raise e\n  File \"/usr/local/lib/python3.10/site-packages/mage_ai/shared/retry.py\", line 38, in retry_func\n    return func(*args, **kwargs)\n  File \"/usr/local/lib/python3.10/site-packages/mage_ai/data_preparation/executors/block_executor.py\", line 621, in __execute_with_retry\n    return self._execute(\n  File \"/usr/local/lib/python3.10/site-packages/mage_ai/data_preparation/executors/block_executor.py\", line 1154, in _execute\n    result = self.block.execute_sync(\n  File \"/usr/local/lib/python3.10/site-packages/mage_ai/data_preparation/models/block/__init__.py\", line 1691, in execute_sync\n    return __execute()\n  File \"/usr/local/lib/python3.10/site-packages/mage_ai/data_preparation/models/block/__init__.py\", line 1668, in __execute\n    raise err\n  File \"/usr/local/lib/python3.10/site-packages/mage_ai/data_preparation/models/block/__init__.py\", line 1570, in __execute\n    output = self.execute_block(\n  File \"/usr/local/lib/python3.10/site-packages/mage_ai/data_preparation/models/block/__init__.py\", line 1910, in execute_block\n    outputs = self._execute_block(\n  File \"/usr/local/lib/python3.10/site-packages/mage_ai/data_preparation/models/block/__init__.py\", line 2073, in _execute_block\n    outputs = self.execute_block_function(\n  File \"/usr/local/lib/python3.10/site-packages/mage_ai/data_preparation/models/block/__init__.py\", line 2169, in execute_block_function\n    output = block_function_updated(*input_vars, **global_vars)\n  File \"<string>\", line 55, in export_data_to_s3\nRuntimeError: [Falha Cr\u00edtica] N\u00e3o foi poss\u00edvel exportar os dados para s3://db-inbev-bronze-layer1/breweries_raw.json ap\u00f3s 3 tentativas.\n", "error_stack": ["  File \"/usr/local/bin/mage\", line 8, in <module>\n    sys.exit(app())\n", "  File \"/usr/local/lib/python3.10/site-packages/typer/main.py\", line 311, in __call__\n    return get_command(self)(*args, **kwargs)\n", "  File \"/usr/local/lib/python3.10/site-packages/click/core.py\", line 1442, in __call__\n    return self.main(*args, **kwargs)\n", "  File \"/usr/local/lib/python3.10/site-packages/typer/core.py\", line 778, in main\n    return _main(\n", "  File \"/usr/local/lib/python3.10/site-packages/typer/core.py\", line 216, in _main\n    rv = self.invoke(ctx)\n", "  File \"/usr/local/lib/python3.10/site-packages/click/core.py\", line 1830, in invoke\n    return _process_result(sub_ctx.command.invoke(sub_ctx))\n", "  File \"/usr/local/lib/python3.10/site-packages/click/core.py\", line 1226, in invoke\n    return ctx.invoke(self.callback, **ctx.params)\n", "  File \"/usr/local/lib/python3.10/site-packages/click/core.py\", line 794, in invoke\n    return callback(*args, **kwargs)\n", "  File \"/usr/local/lib/python3.10/site-packages/typer/main.py\", line 683, in wrapper\n    return callback(**use_params)  # type: ignore\n", "  File \"/usr/local/lib/python3.10/site-packages/mage_ai/cli/main.py\", line 147, in start\n    start_server(\n", "  File \"/usr/local/lib/python3.10/site-packages/mage_ai/server/server.py\", line 809, in start_server\n    scheduler_manager.start_scheduler()\n", "  File \"/usr/local/lib/python3.10/site-packages/mage_ai/server/scheduler_manager.py\", line 108, in start_scheduler\n    proc.start()\n", "  File \"/usr/local/lib/python3.10/multiprocessing/process.py\", line 121, in start\n    self._popen = self._Popen(self)\n", "  File \"/usr/local/lib/python3.10/multiprocessing/context.py\", line 224, in _Popen\n    return _default_context.get_context().Process._Popen(process_obj)\n", "  File \"/usr/local/lib/python3.10/multiprocessing/context.py\", line 281, in _Popen\n    return Popen(process_obj)\n", "  File \"/usr/local/lib/python3.10/multiprocessing/popen_fork.py\", line 19, in __init__\n    self._launch(process_obj)\n", "  File \"/usr/local/lib/python3.10/multiprocessing/popen_fork.py\", line 71, in _launch\n    code = process_obj._bootstrap(parent_sentinel=child_r)\n", "  File \"/usr/local/lib/python3.10/multiprocessing/process.py\", line 314, in _bootstrap\n    self.run()\n", "  File \"/usr/local/lib/python3.10/multiprocessing/process.py\", line 108, in run\n    self._target(*self._args, **self._kwargs)\n", "  File \"/usr/local/lib/python3.10/site-packages/mage_ai/orchestration/db/process.py\", line 15, in start_session_and_run\n    results = target(*args)\n", "  File \"/usr/local/lib/python3.10/site-packages/mage_ai/server/scheduler_manager.py\", line 60, in run_scheduler\n    LoopTimeTrigger().start()\n", "  File \"/usr/local/lib/python3.10/site-packages/mage_ai/orchestration/triggers/loop_time_trigger.py\", line 14, in start\n    self.run()\n", "  File \"/usr/local/lib/python3.10/site-packages/mage_ai/orchestration/triggers/time_trigger.py\", line 11, in run\n    schedule_all()\n", "  File \"/usr/local/lib/python3.10/site-packages/mage_ai/orchestration/pipeline_scheduler_original.py\", line 1730, in schedule_all\n    PipelineScheduler(r).schedule()\n", "  File \"/usr/local/lib/python3.10/site-packages/mage_ai/orchestration/db/__init__.py\", line 159, in func_with_rollback\n    return func(*args, **kwargs)\n", "  File \"/usr/local/lib/python3.10/site-packages/mage_ai/orchestration/pipeline_scheduler_original.py\", line 333, in schedule\n    self.__schedule_blocks(block_runs)\n", "  File \"/usr/local/lib/python3.10/site-packages/mage_ai/orchestration/pipeline_scheduler_original.py\", line 640, in __schedule_blocks\n    job_manager.add_job(\n", "  File \"/usr/local/lib/python3.10/site-packages/mage_ai/orchestration/job_manager.py\", line 20, in add_job\n    self.queue.enqueue(job_id, target, *args, **kwargs)\n", "  File \"/usr/local/lib/python3.10/site-packages/mage_ai/orchestration/queue/process_queue.py\", line 122, in enqueue\n    self.start_worker_pool()\n", "  File \"/usr/local/lib/python3.10/site-packages/mage_ai/orchestration/queue/process_queue.py\", line 199, in start_worker_pool\n    self.worker_pool_proc.start()\n", "  File \"/usr/local/lib/python3.10/multiprocessing/process.py\", line 121, in start\n    self._popen = self._Popen(self)\n", "  File \"/usr/local/lib/python3.10/multiprocessing/context.py\", line 224, in _Popen\n    return _default_context.get_context().Process._Popen(process_obj)\n", "  File \"/usr/local/lib/python3.10/multiprocessing/context.py\", line 281, in _Popen\n    return Popen(process_obj)\n", "  File \"/usr/local/lib/python3.10/multiprocessing/popen_fork.py\", line 19, in __init__\n    self._launch(process_obj)\n", "  File \"/usr/local/lib/python3.10/multiprocessing/popen_fork.py\", line 71, in _launch\n    code = process_obj._bootstrap(parent_sentinel=child_r)\n", "  File \"/usr/local/lib/python3.10/multiprocessing/process.py\", line 314, in _bootstrap\n    self.run()\n", "  File \"/usr/local/lib/python3.10/multiprocessing/process.py\", line 108, in run\n    self._target(*self._args, **self._kwargs)\n", "  File \"/usr/local/lib/python3.10/site-packages/mage_ai/orchestration/queue/process_queue.py\", line 353, in poll_job_and_execute\n    worker.start()\n", "  File \"/usr/local/lib/python3.10/multiprocessing/process.py\", line 121, in start\n    self._popen = self._Popen(self)\n", "  File \"/usr/local/lib/python3.10/multiprocessing/context.py\", line 224, in _Popen\n    return _default_context.get_context().Process._Popen(process_obj)\n", "  File \"/usr/local/lib/python3.10/multiprocessing/context.py\", line 281, in _Popen\n    return Popen(process_obj)\n", "  File \"/usr/local/lib/python3.10/multiprocessing/popen_fork.py\", line 19, in __init__\n    self._launch(process_obj)\n", "  File \"/usr/local/lib/python3.10/multiprocessing/popen_fork.py\", line 71, in _launch\n    code = process_obj._bootstrap(parent_sentinel=child_r)\n", "  File \"/usr/local/lib/python3.10/multiprocessing/process.py\", line 314, in _bootstrap\n    self.run()\n", "  File \"/usr/local/lib/python3.10/site-packages/newrelic/api/background_task.py\", line 117, in wrapper\n    return wrapped(*args, **kwargs)\n", "  File \"/usr/local/lib/python3.10/site-packages/mage_ai/orchestration/queue/process_queue.py\", line 317, in run\n    start_session_and_run(args[1], *args[2], **args[3])\n", "  File \"/usr/local/lib/python3.10/site-packages/mage_ai/orchestration/db/process.py\", line 15, in start_session_and_run\n    results = target(*args)\n", "  File \"/usr/local/lib/python3.10/site-packages/mage_ai/orchestration/pipeline_scheduler_original.py\", line 1235, in run_block\n    return ExecutorFactory.get_block_executor(\n", "  File \"/usr/local/lib/python3.10/site-packages/mage_ai/data_preparation/executors/block_executor.py\", line 649, in execute\n    self.logger.exception(\n", "  File \"/usr/local/lib/python3.10/site-packages/mage_ai/data_preparation/logging/logger.py\", line 30, in exception\n    self.__send_message('exception', message, **kwargs)\n", "  File \"/usr/local/lib/python3.10/site-packages/mage_ai/data_preparation/logging/logger.py\", line 65, in __send_message\n    data['error_stack'] = traceback.format_stack()\n"], "error_stacktrace": "[Falha Cr\u00edtica] N\u00e3o foi poss\u00edvel exportar os dados para s3://db-inbev-bronze-layer1/breweries_raw.json ap\u00f3s 3 tentativas."}
Traceback (most recent call last):
  File "<string>", line 38, in export_data_to_s3
  File "/usr/local/lib/python3.10/site-packages/mage_ai/io/s3.py", line 120, in export
    self.client.put_object(Body=buffer, Bucket=bucket_name, Key=object_key)
  File "/usr/local/lib/python3.10/site-packages/botocore/client.py", line 530, in _api_call
    return self._make_api_call(operation_name, kwargs)
  File "/usr/local/lib/python3.10/site-packages/botocore/client.py", line 964, in _make_api_call
    raise error_class(parsed_response, operation_name)
botocore.errorfactory.NoSuchBucket: An error occurred (NoSuchBucket) when calling the PutObject operation: The specified bucket does not exist

The above exception was the direct cause of the following exception:

Traceback (most recent call last):
  File "/usr/local/lib/python3.10/site-packages/mage_ai/data_preparation/executors/block_executor.py", line 647, in execute
    result = __execute_with_retry()
  File "/usr/local/lib/python3.10/site-packages/mage_ai/shared/retry.py", line 54, in retry_func
    raise e
  File "/usr/local/lib/python3.10/site-packages/mage_ai/shared/retry.py", line 38, in retry_func
    return func(*args, **kwargs)
  File "/usr/local/lib/python3.10/site-packages/mage_ai/data_preparation/executors/block_executor.py", line 621, in __execute_with_retry
    return self._execute(
  File "/usr/local/lib/python3.10/site-packages/mage_ai/data_preparation/executors/block_executor.py", line 1154, in _execute
    result = self.block.execute_sync(
  File "/usr/local/lib/python3.10/site-packages/mage_ai/data_preparation/models/block/__init__.py", line 1691, in execute_sync
    return __execute()
  File "/usr/local/lib/python3.10/site-packages/mage_ai/data_preparation/models/block/__init__.py", line 1668, in __execute
    raise err
  File "/usr/local/lib/python3.10/site-packages/mage_ai/data_preparation/models/block/__init__.py", line 1570, in __execute
    output = self.execute_block(
  File "/usr/local/lib/python3.10/site-packages/mage_ai/data_preparation/models/block/__init__.py", line 1910, in execute_block
    outputs = self._execute_block(
  File "/usr/local/lib/python3.10/site-packages/mage_ai/data_preparation/models/block/__init__.py", line 2073, in _execute_block
    outputs = self.execute_block_function(
  File "/usr/local/lib/python3.10/site-packages/mage_ai/data_preparation/models/block/__init__.py", line 2169, in execute_block_function
    output = block_function_updated(*input_vars, **global_vars)
  File "<string>", line 55, in export_data_to_s3
RuntimeError: [Falha Crítica] Não foi possível exportar os dados para s3://db-inbev-bronze-layer1/breweries_raw.json após 3 tentativas.
