2025-06-30T02:25:32 {"cpu": 0.25146484375, "cpu_total": 6, "cpu_usage": 0.041910807291666664, "memory": 1411.0, "memory_total": 9990.0, "memory_usage": 0.14124124124124124, "pipeline_run_id": 10, "pipeline_schedule_id": 9, "pipeline_uuid": "elt_proj_breweries", "hostname": "4400563e4e3b", "level": "INFO", "message": "Pipeline elt_proj_breweries for run 10 in schedule 9 is alive.", "timestamp": 1751250332.118956, "uuid": "506d7431ead54578bb31666ce7aaea3c"}
2025-06-30T02:25:32 {"cpu": 0.25146484375, "cpu_total": 6, "cpu_usage": 0.041910807291666664, "memory": 1448.0, "memory_total": 9990.0, "memory_usage": 0.14494494494494495, "pipeline_run_id": 10, "pipeline_schedule_id": 9, "pipeline_uuid": "elt_proj_breweries", "hostname": "4400563e4e3b", "level": "INFO", "message": "Pipeline elt_proj_breweries for run 10 in schedule 9 is alive.", "timestamp": 1751250332.391501, "uuid": "3f1a01e550cf4377a800209a358830e8"}
2025-06-30T02:25:32 {"block_run_id": 64, "block_uuid": "import_data_api", "pipeline_run_id": 10, "pipeline_schedule_id": 9, "pipeline_uuid": "elt_proj_breweries", "hostname": "4400563e4e3b", "level": "INFO", "message": "Execute PipelineRun 10, BlockRun 64: pipeline elt_proj_breweries block import_data_api", "timestamp": 1751250332.481863, "uuid": "979c1499f21540b6956da0a08024e15e"}
2025-06-30T02:25:41 {"cpu": 0.24853515625, "cpu_total": 6, "cpu_usage": 0.041422526041666664, "memory": 1466.0, "memory_total": 9990.0, "memory_usage": 0.14674674674674676, "pipeline_run_id": 10, "pipeline_schedule_id": 9, "pipeline_uuid": "elt_proj_breweries", "hostname": "4400563e4e3b", "level": "INFO", "message": "Pipeline elt_proj_breweries for run 10 in schedule 9 is alive.", "timestamp": 1751250341.724018, "uuid": "1b40c093fe5946fc862ac0108470bc54"}
2025-06-30T02:25:52 {"cpu": 0.25732421875, "cpu_total": 6, "cpu_usage": 0.042887369791666664, "memory": 1469.0, "memory_total": 9990.0, "memory_usage": 0.14704704704704705, "pipeline_run_id": 10, "pipeline_schedule_id": 9, "pipeline_uuid": "elt_proj_breweries", "hostname": "4400563e4e3b", "level": "INFO", "message": "Pipeline elt_proj_breweries for run 10 in schedule 9 is alive.", "timestamp": 1751250352.032973, "uuid": "51b136102b234cbc8d0b1cda8f4e1d7c"}
2025-06-30T02:26:01 {"cpu": 0.25439453125, "cpu_total": 6, "cpu_usage": 0.042399088541666664, "memory": 1469.0, "memory_total": 9990.0, "memory_usage": 0.14704704704704705, "pipeline_run_id": 10, "pipeline_schedule_id": 9, "pipeline_uuid": "elt_proj_breweries", "hostname": "4400563e4e3b", "level": "INFO", "message": "Pipeline elt_proj_breweries for run 10 in schedule 9 is alive.", "timestamp": 1751250361.067041, "uuid": "e9a64c1f75974a63a2227a48b52b0afb"}
2025-06-30T02:26:10 {"cpu": 0.25, "cpu_total": 6, "cpu_usage": 0.041666666666666664, "memory": 1480.0, "memory_total": 9990.0, "memory_usage": 0.14814814814814814, "pipeline_run_id": 10, "pipeline_schedule_id": 9, "pipeline_uuid": "elt_proj_breweries", "hostname": "4400563e4e3b", "level": "INFO", "message": "Pipeline elt_proj_breweries for run 10 in schedule 9 is alive.", "timestamp": 1751250370.875546, "uuid": "2e8727420d09428c9e4ed6de377ff7f5"}
2025-06-30T02:26:21 {"cpu": 0.2470703125, "cpu_total": 6, "cpu_usage": 0.041178385416666664, "memory": 1601.0, "memory_total": 9990.0, "memory_usage": 0.16026026026026027, "pipeline_run_id": 10, "pipeline_schedule_id": 9, "pipeline_uuid": "elt_proj_breweries", "hostname": "4400563e4e3b", "level": "INFO", "message": "Pipeline elt_proj_breweries for run 10 in schedule 9 is alive.", "timestamp": 1751250381.170286, "uuid": "f38d99399a224c6ebfb42d1d707bc381"}
2025-06-30T02:26:31 {"cpu": 0.2666015625, "cpu_total": 6, "cpu_usage": 0.04443359375, "memory": 1890.0, "memory_total": 9990.0, "memory_usage": 0.1891891891891892, "pipeline_run_id": 10, "pipeline_schedule_id": 9, "pipeline_uuid": "elt_proj_breweries", "hostname": "4400563e4e3b", "level": "INFO", "message": "Pipeline elt_proj_breweries for run 10 in schedule 9 is alive.", "timestamp": 1751250391.248268, "uuid": "b48195ba9d4543f29a8456d73b906ef7"}
2025-06-30T02:26:32 {"block_run_id": 64, "block_uuid": "import_data_api", "pipeline_run_id": 10, "pipeline_schedule_id": 9, "pipeline_uuid": "elt_proj_breweries", "hostname": "4400563e4e3b", "level": "INFO", "message": "BlockRun 64 (block_uuid: import_data_api) completes.", "timestamp": 1751250392.315868, "uuid": "1cf9acc9e03943a3a6b06ffee4f7f344"}
2025-06-30T02:26:41 {"cpu": 0.26953125, "cpu_total": 6, "cpu_usage": 0.044921875, "memory": 1421.0, "memory_total": 9990.0, "memory_usage": 0.14224224224224224, "pipeline_run_id": 10, "pipeline_schedule_id": 9, "pipeline_uuid": "elt_proj_breweries", "hostname": "4400563e4e3b", "level": "INFO", "message": "Pipeline elt_proj_breweries for run 10 in schedule 9 is alive.", "timestamp": 1751250401.594728, "uuid": "dcad83866057494c891b46984011dad4"}
2025-06-30T02:26:41 {"block_run_id": 65, "block_uuid": "brewery_bronze_export", "pipeline_run_id": 10, "pipeline_schedule_id": 9, "pipeline_uuid": "elt_proj_breweries", "hostname": "4400563e4e3b", "level": "INFO", "message": "Execute PipelineRun 10, BlockRun 65: pipeline elt_proj_breweries block brewery_bronze_export", "timestamp": 1751250401.995269, "uuid": "51513b298c71487182ab728b82dd9614"}
2025-06-30T02:26:46 {"block_run_id": 65, "block_uuid": "brewery_bronze_export", "pipeline_run_id": 10, "pipeline_schedule_id": 9, "pipeline_uuid": "elt_proj_breweries", "hostname": "4400563e4e3b", "level": "EXCEPTION", "message": "BlockRun 65 (block_uuid: brewery_bronze_export) failed.", "timestamp": 1751250406.931557, "uuid": "0fec4157ff7f4aabac189022041234b0", "error": "Traceback (most recent call last):\n  File \"<string>\", line 38, in export_data_to_s3\n  File \"/usr/local/lib/python3.10/site-packages/mage_ai/io/s3.py\", line 120, in export\n    self.client.put_object(Body=buffer, Bucket=bucket_name, Key=object_key)\n  File \"/usr/local/lib/python3.10/site-packages/botocore/client.py\", line 530, in _api_call\n    return self._make_api_call(operation_name, kwargs)\n  File \"/usr/local/lib/python3.10/site-packages/botocore/client.py\", line 964, in _make_api_call\n    raise error_class(parsed_response, operation_name)\nbotocore.errorfactory.NoSuchBucket: An error occurred (NoSuchBucket) when calling the PutObject operation: The specified bucket does not exist\n\nThe above exception was the direct cause of the following exception:\n\nTraceback (most recent call last):\n  File \"/usr/local/lib/python3.10/site-packages/mage_ai/data_preparation/executors/block_executor.py\", line 647, in execute\n    result = __execute_with_retry()\n  File \"/usr/local/lib/python3.10/site-packages/mage_ai/shared/retry.py\", line 54, in retry_func\n    raise e\n  File \"/usr/local/lib/python3.10/site-packages/mage_ai/shared/retry.py\", line 38, in retry_func\n    return func(*args, **kwargs)\n  File \"/usr/local/lib/python3.10/site-packages/mage_ai/data_preparation/executors/block_executor.py\", line 621, in __execute_with_retry\n    return self._execute(\n  File \"/usr/local/lib/python3.10/site-packages/mage_ai/data_preparation/executors/block_executor.py\", line 1154, in _execute\n    result = self.block.execute_sync(\n  File \"/usr/local/lib/python3.10/site-packages/mage_ai/data_preparation/models/block/__init__.py\", line 1691, in execute_sync\n    return __execute()\n  File \"/usr/local/lib/python3.10/site-packages/mage_ai/data_preparation/models/block/__init__.py\", line 1668, in __execute\n    raise err\n  File \"/usr/local/lib/python3.10/site-packages/mage_ai/data_preparation/models/block/__init__.py\", line 1570, in __execute\n    output = self.execute_block(\n  File \"/usr/local/lib/python3.10/site-packages/mage_ai/data_preparation/models/block/__init__.py\", line 1910, in execute_block\n    outputs = self._execute_block(\n  File \"/usr/local/lib/python3.10/site-packages/mage_ai/data_preparation/models/block/__init__.py\", line 2073, in _execute_block\n    outputs = self.execute_block_function(\n  File \"/usr/local/lib/python3.10/site-packages/mage_ai/data_preparation/models/block/__init__.py\", line 2169, in execute_block_function\n    output = block_function_updated(*input_vars, **global_vars)\n  File \"<string>\", line 55, in export_data_to_s3\nRuntimeError: [Falha Cr\u00edtica] N\u00e3o foi poss\u00edvel exportar os dados para s3://db-inbev-bronze-layer1/breweries_raw.json ap\u00f3s 3 tentativas.\n", "error_stack": ["  File \"/usr/local/bin/mage\", line 8, in <module>\n    sys.exit(app())\n", "  File \"/usr/local/lib/python3.10/site-packages/typer/main.py\", line 311, in __call__\n    return get_command(self)(*args, **kwargs)\n", "  File \"/usr/local/lib/python3.10/site-packages/click/core.py\", line 1442, in __call__\n    return self.main(*args, **kwargs)\n", "  File \"/usr/local/lib/python3.10/site-packages/typer/core.py\", line 778, in main\n    return _main(\n", "  File \"/usr/local/lib/python3.10/site-packages/typer/core.py\", line 216, in _main\n    rv = self.invoke(ctx)\n", "  File \"/usr/local/lib/python3.10/site-packages/click/core.py\", line 1830, in invoke\n    return _process_result(sub_ctx.command.invoke(sub_ctx))\n", "  File \"/usr/local/lib/python3.10/site-packages/click/core.py\", line 1226, in invoke\n    return ctx.invoke(self.callback, **ctx.params)\n", "  File \"/usr/local/lib/python3.10/site-packages/click/core.py\", line 794, in invoke\n    return callback(*args, **kwargs)\n", "  File \"/usr/local/lib/python3.10/site-packages/typer/main.py\", line 683, in wrapper\n    return callback(**use_params)  # type: ignore\n", "  File \"/usr/local/lib/python3.10/site-packages/mage_ai/cli/main.py\", line 147, in start\n    start_server(\n", "  File \"/usr/local/lib/python3.10/site-packages/mage_ai/server/server.py\", line 809, in start_server\n    scheduler_manager.start_scheduler()\n", "  File \"/usr/local/lib/python3.10/site-packages/mage_ai/server/scheduler_manager.py\", line 108, in start_scheduler\n    proc.start()\n", "  File \"/usr/local/lib/python3.10/multiprocessing/process.py\", line 121, in start\n    self._popen = self._Popen(self)\n", "  File \"/usr/local/lib/python3.10/multiprocessing/context.py\", line 224, in _Popen\n    return _default_context.get_context().Process._Popen(process_obj)\n", "  File \"/usr/local/lib/python3.10/multiprocessing/context.py\", line 281, in _Popen\n    return Popen(process_obj)\n", "  File \"/usr/local/lib/python3.10/multiprocessing/popen_fork.py\", line 19, in __init__\n    self._launch(process_obj)\n", "  File \"/usr/local/lib/python3.10/multiprocessing/popen_fork.py\", line 71, in _launch\n    code = process_obj._bootstrap(parent_sentinel=child_r)\n", "  File \"/usr/local/lib/python3.10/multiprocessing/process.py\", line 314, in _bootstrap\n    self.run()\n", "  File \"/usr/local/lib/python3.10/multiprocessing/process.py\", line 108, in run\n    self._target(*self._args, **self._kwargs)\n", "  File \"/usr/local/lib/python3.10/site-packages/mage_ai/orchestration/db/process.py\", line 15, in start_session_and_run\n    results = target(*args)\n", "  File \"/usr/local/lib/python3.10/site-packages/mage_ai/server/scheduler_manager.py\", line 60, in run_scheduler\n    LoopTimeTrigger().start()\n", "  File \"/usr/local/lib/python3.10/site-packages/mage_ai/orchestration/triggers/loop_time_trigger.py\", line 14, in start\n    self.run()\n", "  File \"/usr/local/lib/python3.10/site-packages/mage_ai/orchestration/triggers/time_trigger.py\", line 11, in run\n    schedule_all()\n", "  File \"/usr/local/lib/python3.10/site-packages/mage_ai/orchestration/pipeline_scheduler_original.py\", line 1730, in schedule_all\n    PipelineScheduler(r).schedule()\n", "  File \"/usr/local/lib/python3.10/site-packages/mage_ai/orchestration/db/__init__.py\", line 159, in func_with_rollback\n    return func(*args, **kwargs)\n", "  File \"/usr/local/lib/python3.10/site-packages/mage_ai/orchestration/pipeline_scheduler_original.py\", line 333, in schedule\n    self.__schedule_blocks(block_runs)\n", "  File \"/usr/local/lib/python3.10/site-packages/mage_ai/orchestration/pipeline_scheduler_original.py\", line 640, in __schedule_blocks\n    job_manager.add_job(\n", "  File \"/usr/local/lib/python3.10/site-packages/mage_ai/orchestration/job_manager.py\", line 20, in add_job\n    self.queue.enqueue(job_id, target, *args, **kwargs)\n", "  File \"/usr/local/lib/python3.10/site-packages/mage_ai/orchestration/queue/process_queue.py\", line 122, in enqueue\n    self.start_worker_pool()\n", "  File \"/usr/local/lib/python3.10/site-packages/mage_ai/orchestration/queue/process_queue.py\", line 199, in start_worker_pool\n    self.worker_pool_proc.start()\n", "  File \"/usr/local/lib/python3.10/multiprocessing/process.py\", line 121, in start\n    self._popen = self._Popen(self)\n", "  File \"/usr/local/lib/python3.10/multiprocessing/context.py\", line 224, in _Popen\n    return _default_context.get_context().Process._Popen(process_obj)\n", "  File \"/usr/local/lib/python3.10/multiprocessing/context.py\", line 281, in _Popen\n    return Popen(process_obj)\n", "  File \"/usr/local/lib/python3.10/multiprocessing/popen_fork.py\", line 19, in __init__\n    self._launch(process_obj)\n", "  File \"/usr/local/lib/python3.10/multiprocessing/popen_fork.py\", line 71, in _launch\n    code = process_obj._bootstrap(parent_sentinel=child_r)\n", "  File \"/usr/local/lib/python3.10/multiprocessing/process.py\", line 314, in _bootstrap\n    self.run()\n", "  File \"/usr/local/lib/python3.10/multiprocessing/process.py\", line 108, in run\n    self._target(*self._args, **self._kwargs)\n", "  File \"/usr/local/lib/python3.10/site-packages/mage_ai/orchestration/queue/process_queue.py\", line 353, in poll_job_and_execute\n    worker.start()\n", "  File \"/usr/local/lib/python3.10/multiprocessing/process.py\", line 121, in start\n    self._popen = self._Popen(self)\n", "  File \"/usr/local/lib/python3.10/multiprocessing/context.py\", line 224, in _Popen\n    return _default_context.get_context().Process._Popen(process_obj)\n", "  File \"/usr/local/lib/python3.10/multiprocessing/context.py\", line 281, in _Popen\n    return Popen(process_obj)\n", "  File \"/usr/local/lib/python3.10/multiprocessing/popen_fork.py\", line 19, in __init__\n    self._launch(process_obj)\n", "  File \"/usr/local/lib/python3.10/multiprocessing/popen_fork.py\", line 71, in _launch\n    code = process_obj._bootstrap(parent_sentinel=child_r)\n", "  File \"/usr/local/lib/python3.10/multiprocessing/process.py\", line 314, in _bootstrap\n    self.run()\n", "  File \"/usr/local/lib/python3.10/site-packages/newrelic/api/background_task.py\", line 117, in wrapper\n    return wrapped(*args, **kwargs)\n", "  File \"/usr/local/lib/python3.10/site-packages/mage_ai/orchestration/queue/process_queue.py\", line 317, in run\n    start_session_and_run(args[1], *args[2], **args[3])\n", "  File \"/usr/local/lib/python3.10/site-packages/mage_ai/orchestration/db/process.py\", line 15, in start_session_and_run\n    results = target(*args)\n", "  File \"/usr/local/lib/python3.10/site-packages/mage_ai/orchestration/pipeline_scheduler_original.py\", line 1235, in run_block\n    return ExecutorFactory.get_block_executor(\n", "  File \"/usr/local/lib/python3.10/site-packages/mage_ai/data_preparation/executors/block_executor.py\", line 682, in execute\n    on_failure(\n", "  File \"/usr/local/lib/python3.10/site-packages/mage_ai/orchestration/db/__init__.py\", line 159, in func_with_rollback\n    return func(*args, **kwargs)\n", "  File \"/usr/local/lib/python3.10/site-packages/mage_ai/orchestration/pipeline_scheduler_original.py\", line 464, in on_block_failure\n    self.logger.exception(\n", "  File \"/usr/local/lib/python3.10/site-packages/mage_ai/data_preparation/logging/logger.py\", line 30, in exception\n    self.__send_message('exception', message, **kwargs)\n", "  File \"/usr/local/lib/python3.10/site-packages/mage_ai/data_preparation/logging/logger.py\", line 65, in __send_message\n    data['error_stack'] = traceback.format_stack()\n"], "error_stacktrace": "[Falha Cr\u00edtica] N\u00e3o foi poss\u00edvel exportar os dados para s3://db-inbev-bronze-layer1/breweries_raw.json ap\u00f3s 3 tentativas."}
Traceback (most recent call last):
  File "<string>", line 38, in export_data_to_s3
  File "/usr/local/lib/python3.10/site-packages/mage_ai/io/s3.py", line 120, in export
    self.client.put_object(Body=buffer, Bucket=bucket_name, Key=object_key)
  File "/usr/local/lib/python3.10/site-packages/botocore/client.py", line 530, in _api_call
    return self._make_api_call(operation_name, kwargs)
  File "/usr/local/lib/python3.10/site-packages/botocore/client.py", line 964, in _make_api_call
    raise error_class(parsed_response, operation_name)
botocore.errorfactory.NoSuchBucket: An error occurred (NoSuchBucket) when calling the PutObject operation: The specified bucket does not exist

The above exception was the direct cause of the following exception:

Traceback (most recent call last):
  File "/usr/local/lib/python3.10/site-packages/mage_ai/data_preparation/executors/block_executor.py", line 647, in execute
    result = __execute_with_retry()
  File "/usr/local/lib/python3.10/site-packages/mage_ai/shared/retry.py", line 54, in retry_func
    raise e
  File "/usr/local/lib/python3.10/site-packages/mage_ai/shared/retry.py", line 38, in retry_func
    return func(*args, **kwargs)
  File "/usr/local/lib/python3.10/site-packages/mage_ai/data_preparation/executors/block_executor.py", line 621, in __execute_with_retry
    return self._execute(
  File "/usr/local/lib/python3.10/site-packages/mage_ai/data_preparation/executors/block_executor.py", line 1154, in _execute
    result = self.block.execute_sync(
  File "/usr/local/lib/python3.10/site-packages/mage_ai/data_preparation/models/block/__init__.py", line 1691, in execute_sync
    return __execute()
  File "/usr/local/lib/python3.10/site-packages/mage_ai/data_preparation/models/block/__init__.py", line 1668, in __execute
    raise err
  File "/usr/local/lib/python3.10/site-packages/mage_ai/data_preparation/models/block/__init__.py", line 1570, in __execute
    output = self.execute_block(
  File "/usr/local/lib/python3.10/site-packages/mage_ai/data_preparation/models/block/__init__.py", line 1910, in execute_block
    outputs = self._execute_block(
  File "/usr/local/lib/python3.10/site-packages/mage_ai/data_preparation/models/block/__init__.py", line 2073, in _execute_block
    outputs = self.execute_block_function(
  File "/usr/local/lib/python3.10/site-packages/mage_ai/data_preparation/models/block/__init__.py", line 2169, in execute_block_function
    output = block_function_updated(*input_vars, **global_vars)
  File "<string>", line 55, in export_data_to_s3
RuntimeError: [Falha Crítica] Não foi possível exportar os dados para s3://db-inbev-bronze-layer1/breweries_raw.json após 3 tentativas.
2025-06-30T02:26:48 {"cpu": 0.2724609375, "cpu_total": 6, "cpu_usage": 0.04541015625, "memory": 1416.0, "memory_total": 9990.0, "memory_usage": 0.14174174174174173, "pipeline_run_id": 10, "pipeline_schedule_id": 9, "pipeline_uuid": "elt_proj_breweries", "hostname": "4400563e4e3b", "level": "INFO", "message": "Pipeline elt_proj_breweries for run 10 in schedule 9 is alive.", "timestamp": 1751250408.158113, "uuid": "615e1379d7924e3ab4c3be31d44ba8ba"}
