2025-06-30T04:59:05 {"cpu": 0.32763671875, "cpu_total": 6, "cpu_usage": 0.054606119791666664, "memory": 1330.0, "memory_total": 9990.0, "memory_usage": 0.13313313313313313, "pipeline_run_id": 37, "pipeline_schedule_id": 18, "pipeline_uuid": "elt_proj_breweries", "hostname": "8765c09e128e", "level": "INFO", "message": "Pipeline elt_proj_breweries for run 37 in schedule 18 is alive.", "timestamp": 1751259545.093265, "uuid": "6605d19afb254b4299c7109ae6a77fc9"}
2025-06-30T04:59:05 {"cpu": 0.32763671875, "cpu_total": 6, "cpu_usage": 0.054606119791666664, "memory": 1368.0, "memory_total": 9990.0, "memory_usage": 0.13693693693693693, "pipeline_run_id": 37, "pipeline_schedule_id": 18, "pipeline_uuid": "elt_proj_breweries", "hostname": "8765c09e128e", "level": "INFO", "message": "Pipeline elt_proj_breweries for run 37 in schedule 18 is alive.", "timestamp": 1751259545.360459, "uuid": "643940413fd74a44a4c12f78e338f343"}
2025-06-30T04:59:05 {"block_run_id": 118, "block_uuid": "import_data_api", "pipeline_run_id": 37, "pipeline_schedule_id": 18, "pipeline_uuid": "elt_proj_breweries", "hostname": "8765c09e128e", "level": "INFO", "message": "Execute PipelineRun 37, BlockRun 118: pipeline elt_proj_breweries block import_data_api", "timestamp": 1751259545.43277, "uuid": "eab53a8850fc4dbc865bebba507b960d"}
2025-06-30T04:59:14 {"cpu": 0.3349609375, "cpu_total": 6, "cpu_usage": 0.055826822916666664, "memory": 1392.0, "memory_total": 9990.0, "memory_usage": 0.13933933933933934, "pipeline_run_id": 37, "pipeline_schedule_id": 18, "pipeline_uuid": "elt_proj_breweries", "hostname": "8765c09e128e", "level": "INFO", "message": "Pipeline elt_proj_breweries for run 37 in schedule 18 is alive.", "timestamp": 1751259554.673322, "uuid": "a48b60fe1f514505abbfeaec42cd35fa"}
2025-06-30T04:59:24 {"cpu": 0.34228515625, "cpu_total": 6, "cpu_usage": 0.057047526041666664, "memory": 1461.0, "memory_total": 9990.0, "memory_usage": 0.14624624624624624, "pipeline_run_id": 37, "pipeline_schedule_id": 18, "pipeline_uuid": "elt_proj_breweries", "hostname": "8765c09e128e", "level": "INFO", "message": "Pipeline elt_proj_breweries for run 37 in schedule 18 is alive.", "timestamp": 1751259564.971527, "uuid": "1d4802ff274641f9a0b63932043df56a"}
2025-06-30T04:59:34 {"cpu": 0.35498046875, "cpu_total": 6, "cpu_usage": 0.059163411458333336, "memory": 1742.0, "memory_total": 9990.0, "memory_usage": 0.17437437437437436, "pipeline_run_id": 37, "pipeline_schedule_id": 18, "pipeline_uuid": "elt_proj_breweries", "hostname": "8765c09e128e", "level": "INFO", "message": "Pipeline elt_proj_breweries for run 37 in schedule 18 is alive.", "timestamp": 1751259574.400421, "uuid": "aa14206a6ad54b84a0114ef637cc0fbb"}
2025-06-30T04:59:38 {"block_run_id": 118, "block_uuid": "import_data_api", "pipeline_run_id": 37, "pipeline_schedule_id": 18, "pipeline_uuid": "elt_proj_breweries", "hostname": "8765c09e128e", "level": "INFO", "message": "BlockRun 118 (block_uuid: import_data_api) completes.", "timestamp": 1751259578.292452, "uuid": "c0b2a61cfddf48908cc251b93233eb01"}
2025-06-30T04:59:44 {"cpu": 0.36181640625, "cpu_total": 6, "cpu_usage": 0.060302734375, "memory": 1352.0, "memory_total": 9990.0, "memory_usage": 0.13533533533533534, "pipeline_run_id": 37, "pipeline_schedule_id": 18, "pipeline_uuid": "elt_proj_breweries", "hostname": "8765c09e128e", "level": "INFO", "message": "Pipeline elt_proj_breweries for run 37 in schedule 18 is alive.", "timestamp": 1751259584.758746, "uuid": "70d4e21ea50a4801bc0f0e25b8abbb22"}
2025-06-30T04:59:45 {"block_run_id": 119, "block_uuid": "brewery_bronze_export", "pipeline_run_id": 37, "pipeline_schedule_id": 18, "pipeline_uuid": "elt_proj_breweries", "hostname": "8765c09e128e", "level": "INFO", "message": "Execute PipelineRun 37, BlockRun 119: pipeline elt_proj_breweries block brewery_bronze_export", "timestamp": 1751259585.112396, "uuid": "bd3f0a3fc4e340df901a068be4233397"}
2025-06-30T04:59:53 {"block_run_id": 119, "block_uuid": "brewery_bronze_export", "pipeline_run_id": 37, "pipeline_schedule_id": 18, "pipeline_uuid": "elt_proj_breweries", "hostname": "8765c09e128e", "level": "EXCEPTION", "message": "BlockRun 119 (block_uuid: brewery_bronze_export) failed.", "timestamp": 1751259593.537454, "uuid": "30c0e39a20834ef1a416f81a6b740f98", "error": "Traceback (most recent call last):\n  File \"<string>\", line 38, in export_data_to_s3\n  File \"/usr/local/lib/python3.10/site-packages/mage_ai/io/s3.py\", line 120, in export\n    self.client.put_object(Body=buffer, Bucket=bucket_name, Key=object_key)\n  File \"/usr/local/lib/python3.10/site-packages/botocore/client.py\", line 530, in _api_call\n    return self._make_api_call(operation_name, kwargs)\n  File \"/usr/local/lib/python3.10/site-packages/botocore/client.py\", line 964, in _make_api_call\n    raise error_class(parsed_response, operation_name)\nbotocore.errorfactory.NoSuchBucket: An error occurred (NoSuchBucket) when calling the PutObject operation: The specified bucket does not exist\n\nThe above exception was the direct cause of the following exception:\n\nTraceback (most recent call last):\n  File \"/usr/local/lib/python3.10/site-packages/mage_ai/data_preparation/executors/block_executor.py\", line 647, in execute\n    result = __execute_with_retry()\n  File \"/usr/local/lib/python3.10/site-packages/mage_ai/shared/retry.py\", line 54, in retry_func\n    raise e\n  File \"/usr/local/lib/python3.10/site-packages/mage_ai/shared/retry.py\", line 38, in retry_func\n    return func(*args, **kwargs)\n  File \"/usr/local/lib/python3.10/site-packages/mage_ai/data_preparation/executors/block_executor.py\", line 621, in __execute_with_retry\n    return self._execute(\n  File \"/usr/local/lib/python3.10/site-packages/mage_ai/data_preparation/executors/block_executor.py\", line 1154, in _execute\n    result = self.block.execute_sync(\n  File \"/usr/local/lib/python3.10/site-packages/mage_ai/data_preparation/models/block/__init__.py\", line 1691, in execute_sync\n    return __execute()\n  File \"/usr/local/lib/python3.10/site-packages/mage_ai/data_preparation/models/block/__init__.py\", line 1668, in __execute\n    raise err\n  File \"/usr/local/lib/python3.10/site-packages/mage_ai/data_preparation/models/block/__init__.py\", line 1570, in __execute\n    output = self.execute_block(\n  File \"/usr/local/lib/python3.10/site-packages/mage_ai/data_preparation/models/block/__init__.py\", line 1910, in execute_block\n    outputs = self._execute_block(\n  File \"/usr/local/lib/python3.10/site-packages/mage_ai/data_preparation/models/block/__init__.py\", line 2073, in _execute_block\n    outputs = self.execute_block_function(\n  File \"/usr/local/lib/python3.10/site-packages/mage_ai/data_preparation/models/block/__init__.py\", line 2169, in execute_block_function\n    output = block_function_updated(*input_vars, **global_vars)\n  File \"<string>\", line 55, in export_data_to_s3\nRuntimeError: [Falha Cr\u00edtica] N\u00e3o foi poss\u00edvel exportar os dados para s3://db-inbev-bronze-layer1/breweries_raw.json ap\u00f3s 3 tentativas.\n", "error_stack": ["  File \"/usr/local/bin/mage\", line 8, in <module>\n    sys.exit(app())\n", "  File \"/usr/local/lib/python3.10/site-packages/typer/main.py\", line 311, in __call__\n    return get_command(self)(*args, **kwargs)\n", "  File \"/usr/local/lib/python3.10/site-packages/click/core.py\", line 1442, in __call__\n    return self.main(*args, **kwargs)\n", "  File \"/usr/local/lib/python3.10/site-packages/typer/core.py\", line 778, in main\n    return _main(\n", "  File \"/usr/local/lib/python3.10/site-packages/typer/core.py\", line 216, in _main\n    rv = self.invoke(ctx)\n", "  File \"/usr/local/lib/python3.10/site-packages/click/core.py\", line 1830, in invoke\n    return _process_result(sub_ctx.command.invoke(sub_ctx))\n", "  File \"/usr/local/lib/python3.10/site-packages/click/core.py\", line 1226, in invoke\n    return ctx.invoke(self.callback, **ctx.params)\n", "  File \"/usr/local/lib/python3.10/site-packages/click/core.py\", line 794, in invoke\n    return callback(*args, **kwargs)\n", "  File \"/usr/local/lib/python3.10/site-packages/typer/main.py\", line 683, in wrapper\n    return callback(**use_params)  # type: ignore\n", "  File \"/usr/local/lib/python3.10/site-packages/mage_ai/cli/main.py\", line 147, in start\n    start_server(\n", "  File \"/usr/local/lib/python3.10/site-packages/mage_ai/server/server.py\", line 809, in start_server\n    scheduler_manager.start_scheduler()\n", "  File \"/usr/local/lib/python3.10/site-packages/mage_ai/server/scheduler_manager.py\", line 108, in start_scheduler\n    proc.start()\n", "  File \"/usr/local/lib/python3.10/multiprocessing/process.py\", line 121, in start\n    self._popen = self._Popen(self)\n", "  File \"/usr/local/lib/python3.10/multiprocessing/context.py\", line 224, in _Popen\n    return _default_context.get_context().Process._Popen(process_obj)\n", "  File \"/usr/local/lib/python3.10/multiprocessing/context.py\", line 281, in _Popen\n    return Popen(process_obj)\n", "  File \"/usr/local/lib/python3.10/multiprocessing/popen_fork.py\", line 19, in __init__\n    self._launch(process_obj)\n", "  File \"/usr/local/lib/python3.10/multiprocessing/popen_fork.py\", line 71, in _launch\n    code = process_obj._bootstrap(parent_sentinel=child_r)\n", "  File \"/usr/local/lib/python3.10/multiprocessing/process.py\", line 314, in _bootstrap\n    self.run()\n", "  File \"/usr/local/lib/python3.10/multiprocessing/process.py\", line 108, in run\n    self._target(*self._args, **self._kwargs)\n", "  File \"/usr/local/lib/python3.10/site-packages/mage_ai/orchestration/db/process.py\", line 15, in start_session_and_run\n    results = target(*args)\n", "  File \"/usr/local/lib/python3.10/site-packages/mage_ai/server/scheduler_manager.py\", line 60, in run_scheduler\n    LoopTimeTrigger().start()\n", "  File \"/usr/local/lib/python3.10/site-packages/mage_ai/orchestration/triggers/loop_time_trigger.py\", line 14, in start\n    self.run()\n", "  File \"/usr/local/lib/python3.10/site-packages/mage_ai/orchestration/triggers/time_trigger.py\", line 11, in run\n    schedule_all()\n", "  File \"/usr/local/lib/python3.10/site-packages/mage_ai/orchestration/pipeline_scheduler_original.py\", line 1730, in schedule_all\n    PipelineScheduler(r).schedule()\n", "  File \"/usr/local/lib/python3.10/site-packages/mage_ai/orchestration/db/__init__.py\", line 159, in func_with_rollback\n    return func(*args, **kwargs)\n", "  File \"/usr/local/lib/python3.10/site-packages/mage_ai/orchestration/pipeline_scheduler_original.py\", line 333, in schedule\n    self.__schedule_blocks(block_runs)\n", "  File \"/usr/local/lib/python3.10/site-packages/mage_ai/orchestration/pipeline_scheduler_original.py\", line 640, in __schedule_blocks\n    job_manager.add_job(\n", "  File \"/usr/local/lib/python3.10/site-packages/mage_ai/orchestration/job_manager.py\", line 20, in add_job\n    self.queue.enqueue(job_id, target, *args, **kwargs)\n", "  File \"/usr/local/lib/python3.10/site-packages/mage_ai/orchestration/queue/process_queue.py\", line 122, in enqueue\n    self.start_worker_pool()\n", "  File \"/usr/local/lib/python3.10/site-packages/mage_ai/orchestration/queue/process_queue.py\", line 199, in start_worker_pool\n    self.worker_pool_proc.start()\n", "  File \"/usr/local/lib/python3.10/multiprocessing/process.py\", line 121, in start\n    self._popen = self._Popen(self)\n", "  File \"/usr/local/lib/python3.10/multiprocessing/context.py\", line 224, in _Popen\n    return _default_context.get_context().Process._Popen(process_obj)\n", "  File \"/usr/local/lib/python3.10/multiprocessing/context.py\", line 281, in _Popen\n    return Popen(process_obj)\n", "  File \"/usr/local/lib/python3.10/multiprocessing/popen_fork.py\", line 19, in __init__\n    self._launch(process_obj)\n", "  File \"/usr/local/lib/python3.10/multiprocessing/popen_fork.py\", line 71, in _launch\n    code = process_obj._bootstrap(parent_sentinel=child_r)\n", "  File \"/usr/local/lib/python3.10/multiprocessing/process.py\", line 314, in _bootstrap\n    self.run()\n", "  File \"/usr/local/lib/python3.10/multiprocessing/process.py\", line 108, in run\n    self._target(*self._args, **self._kwargs)\n", "  File \"/usr/local/lib/python3.10/site-packages/mage_ai/orchestration/queue/process_queue.py\", line 353, in poll_job_and_execute\n    worker.start()\n", "  File \"/usr/local/lib/python3.10/multiprocessing/process.py\", line 121, in start\n    self._popen = self._Popen(self)\n", "  File \"/usr/local/lib/python3.10/multiprocessing/context.py\", line 224, in _Popen\n    return _default_context.get_context().Process._Popen(process_obj)\n", "  File \"/usr/local/lib/python3.10/multiprocessing/context.py\", line 281, in _Popen\n    return Popen(process_obj)\n", "  File \"/usr/local/lib/python3.10/multiprocessing/popen_fork.py\", line 19, in __init__\n    self._launch(process_obj)\n", "  File \"/usr/local/lib/python3.10/multiprocessing/popen_fork.py\", line 71, in _launch\n    code = process_obj._bootstrap(parent_sentinel=child_r)\n", "  File \"/usr/local/lib/python3.10/multiprocessing/process.py\", line 314, in _bootstrap\n    self.run()\n", "  File \"/usr/local/lib/python3.10/site-packages/newrelic/api/background_task.py\", line 117, in wrapper\n    return wrapped(*args, **kwargs)\n", "  File \"/usr/local/lib/python3.10/site-packages/mage_ai/orchestration/queue/process_queue.py\", line 317, in run\n    start_session_and_run(args[1], *args[2], **args[3])\n", "  File \"/usr/local/lib/python3.10/site-packages/mage_ai/orchestration/db/process.py\", line 15, in start_session_and_run\n    results = target(*args)\n", "  File \"/usr/local/lib/python3.10/site-packages/mage_ai/orchestration/pipeline_scheduler_original.py\", line 1235, in run_block\n    return ExecutorFactory.get_block_executor(\n", "  File \"/usr/local/lib/python3.10/site-packages/mage_ai/data_preparation/executors/block_executor.py\", line 682, in execute\n    on_failure(\n", "  File \"/usr/local/lib/python3.10/site-packages/mage_ai/orchestration/db/__init__.py\", line 159, in func_with_rollback\n    return func(*args, **kwargs)\n", "  File \"/usr/local/lib/python3.10/site-packages/mage_ai/orchestration/pipeline_scheduler_original.py\", line 464, in on_block_failure\n    self.logger.exception(\n", "  File \"/usr/local/lib/python3.10/site-packages/mage_ai/data_preparation/logging/logger.py\", line 30, in exception\n    self.__send_message('exception', message, **kwargs)\n", "  File \"/usr/local/lib/python3.10/site-packages/mage_ai/data_preparation/logging/logger.py\", line 65, in __send_message\n    data['error_stack'] = traceback.format_stack()\n"], "error_stacktrace": "[Falha Cr\u00edtica] N\u00e3o foi poss\u00edvel exportar os dados para s3://db-inbev-bronze-layer1/breweries_raw.json ap\u00f3s 3 tentativas."}
Traceback (most recent call last):
  File "<string>", line 38, in export_data_to_s3
  File "/usr/local/lib/python3.10/site-packages/mage_ai/io/s3.py", line 120, in export
    self.client.put_object(Body=buffer, Bucket=bucket_name, Key=object_key)
  File "/usr/local/lib/python3.10/site-packages/botocore/client.py", line 530, in _api_call
    return self._make_api_call(operation_name, kwargs)
  File "/usr/local/lib/python3.10/site-packages/botocore/client.py", line 964, in _make_api_call
    raise error_class(parsed_response, operation_name)
botocore.errorfactory.NoSuchBucket: An error occurred (NoSuchBucket) when calling the PutObject operation: The specified bucket does not exist

The above exception was the direct cause of the following exception:

Traceback (most recent call last):
  File "/usr/local/lib/python3.10/site-packages/mage_ai/data_preparation/executors/block_executor.py", line 647, in execute
    result = __execute_with_retry()
  File "/usr/local/lib/python3.10/site-packages/mage_ai/shared/retry.py", line 54, in retry_func
    raise e
  File "/usr/local/lib/python3.10/site-packages/mage_ai/shared/retry.py", line 38, in retry_func
    return func(*args, **kwargs)
  File "/usr/local/lib/python3.10/site-packages/mage_ai/data_preparation/executors/block_executor.py", line 621, in __execute_with_retry
    return self._execute(
  File "/usr/local/lib/python3.10/site-packages/mage_ai/data_preparation/executors/block_executor.py", line 1154, in _execute
    result = self.block.execute_sync(
  File "/usr/local/lib/python3.10/site-packages/mage_ai/data_preparation/models/block/__init__.py", line 1691, in execute_sync
    return __execute()
  File "/usr/local/lib/python3.10/site-packages/mage_ai/data_preparation/models/block/__init__.py", line 1668, in __execute
    raise err
  File "/usr/local/lib/python3.10/site-packages/mage_ai/data_preparation/models/block/__init__.py", line 1570, in __execute
    output = self.execute_block(
  File "/usr/local/lib/python3.10/site-packages/mage_ai/data_preparation/models/block/__init__.py", line 1910, in execute_block
    outputs = self._execute_block(
  File "/usr/local/lib/python3.10/site-packages/mage_ai/data_preparation/models/block/__init__.py", line 2073, in _execute_block
    outputs = self.execute_block_function(
  File "/usr/local/lib/python3.10/site-packages/mage_ai/data_preparation/models/block/__init__.py", line 2169, in execute_block_function
    output = block_function_updated(*input_vars, **global_vars)
  File "<string>", line 55, in export_data_to_s3
RuntimeError: [Falha Crítica] Não foi possível exportar os dados para s3://db-inbev-bronze-layer1/breweries_raw.json após 3 tentativas.
2025-06-30T04:59:54 {"cpu": 0.35791015625, "cpu_total": 6, "cpu_usage": 0.059651692708333336, "memory": 1344.0, "memory_total": 9990.0, "memory_usage": 0.13453453453453454, "pipeline_run_id": 37, "pipeline_schedule_id": 18, "pipeline_uuid": "elt_proj_breweries", "hostname": "8765c09e128e", "level": "INFO", "message": "Pipeline elt_proj_breweries for run 37 in schedule 18 is alive.", "timestamp": 1751259594.329762, "uuid": "89901cfaf94744c5a278b8f5b0a50194"}
